Workbook

Sheet LEIAME
A1: DF Síndicos · Plano de Contingência da Água — Planilha-mestre (modelo genérico)
A3: Versão | B3: 0.1 — rascunho para revisão técnica · 2026-10-02 · gerada a partir do catálogo v2 (195 itens)
A4: O que é | B4: Ficha por condomínio do plano de contingência, manutenção e monitoramento dos sistemas de água. Esta é a versão em branco: não tem dado de nenhum condomínio.
A5: Como usar | B5: 1) Faça uma cópia por condomínio e salve no OneDrive (nunca no GitHub). 2) Preencha 'Condominio' e 'Contatos'. 3) Em 'Catalogo', marque S, N ou ? em cada item. 4) Veja a 'Matriz' (quais cenários valem para o prédio) e o 'Resumo'. 5) Em 'Manutencao', registre responsável, periodicidade e última execução de cada família. 6) Faça a 'Autovistoria' com a equipe residente. 7) Registre ocorrências em 'Incidentes'.
A6: Regra de ouro | B6: 'Não sei' (?) e célula em branco valem como PIOR CASO: o item é tratado como existente e sem proteção, e entra na vistoria. Foi esse tipo de ponto, que ninguém sabia que existia, que causou os dois episódios.
A7: Células amarelas (texto azul) | B7: São as únicas que você preenche. Todo o resto é fórmula ou texto fixo.
A8: Abas | B8: Resumo (semáforo e contagens, calculado) · Condominio · Contatos (escada de escalonamento) · Catalogo (195 itens) · Matriz (item × cenário) · Manutencao (16 famílias) · Autovistoria (42 itens, Cenário 1) · Incidentes (registro)
A9: Cenários | B9: 1 Contaminação cruzada · 2 Falta de água · 3 Água fora do padrão · 4 Vazamento e alagamento · 5 Falha de bomba ou energia · 6 Incêndio com reserva indisponível · 7 Refluxo de esgoto · 8 Falha do tratamento químico · 9 Contaminação do reservatório · T Comunicação de crise. Os procedimentos dos cenários 1 a 9 e do T (comunicação de crise) estão em entregas/plano-contingencia-agua/cenarios/; os checklists de ronda e do relatório mensal dos fornecedores estão em .../rotinas/.
A10: Limites | B10: A planilha orienta e organiza; não substitui responsável técnico, laudo nem projeto. A coluna 'Cenários' do catálogo foi preenchida por critério técnico geral e deve ser revisada na primeira ficha real. A autovistoria não certifica dispositivo antirretorno nem teste de pressão.
A11: Referências | B11: As marcadas ✔ no catálogo tiveram existência e escopo geral conferidos por pesquisa web; nenhuma norma ABNT foi lida. As marcadas ◻ precisam de confirmação. Ver catalogo-v2.md.
A12: Se o catálogo mudar | B12: O catálogo-fonte é o Markdown deste projeto. Ao revisá-lo, peça para regerar a planilha e copie as respostas S/N/? de cada condomínio pelos IDs, que não mudam.
A14: Exemplos de preenchimento (só para mostrar o formato; não copie)
A15: Catalogo, item C14 | B15: Existe? S · Local: sala do chiller, cobertura · Foto: IMG_0412 · Data: 15/03/2026 · Quem informou: encarregado de manutenção
A16: Catalogo, item A13 | B16: Existe? ? · Observação: ninguém soube dizer se há disconector na reposição · isso vira VISTORIAR e vale como sem proteção
A17: Manutencao, família 1 | B17: Responsável: empresa de limpeza de reservatório · Periodicidade: 180 · Última execução: 10/02/2026 → a planilha calcula a próxima data e o status
A18: Autovistoria, item 1.6 | B18: Resposta: N (não há mangueira conectada) → Status OK. Se a resposta fosse S, o status seria VERMELHO
A19: Incidentes | B19: Data: 02/10/2026 14:30 · Cenário: 1 · Ramo: A · Local: 8º andar, copa · Observado: água rosa na torneira · Status: Aberto

Sheet Resumo
A1: Resumo da ficha
A2: Tudo nesta aba é calculado; não digite aqui.
A4: Situação geral
A5: Semáforo geral | B5: =IF(B34>0,"VERMELHO",IF(OR(B35>0,B13>0,B30>0),"AMARELO","VERDE")) | C5: VERMELHO: há item crítico da autovistoria com risco ou '?'. AMARELO: há pendência (vistoria, manutenção vencida, item não crítico). VERDE: sem pendências. Não substitui parecer técnico.
A7: Catálogo (o que existe no prédio)
A8: Itens no catálogo | B8: =COUNTA(Catalogo!$A$2:$A$196)
A9: Existem (S) | B9: =COUNTIF(Catalogo!$H$2:$H$196,"S")
A10: Não existem (N) | B10: =COUNTIF(Catalogo!$H$2:$H$196,"N")
A11: Não sei (?) | B11: =COUNTIF(Catalogo!$H$2:$H$196,"~?") | C11: Vale como pior caso: tratar como sem proteção
A12: Em branco (não preenchidos) | B12: =COUNTBLANK(Catalogo!$H$2:$H$196)
A13: Pendências de vistoria (? + em branco) | B13: =B11+B12
A14: % preenchido (S + N + ?) | B14: =IF(B8=0,0,(B9+B10+B11)/B8)
A16: Matriz sistema × cenário (itens aplicáveis)
A17: 1 Contaminação cruzada | B17: =COUNTIF(Matriz!D$2:D$196,"●")
A18: 2 Falta de água | B18: =COUNTIF(Matriz!E$2:E$196,"●")
A19: 3 Água fora do padrão | B19: =COUNTIF(Matriz!F$2:F$196,"●")
A20: 4 Vazamento e alagamento | B20: =COUNTIF(Matriz!G$2:G$196,"●")
A21: 5 Falha de bomba ou energia | B21: =COUNTIF(Matriz!H$2:H$196,"●")
A22: 6 Incêndio | B22: =COUNTIF(Matriz!I$2:I$196,"●")
A23: 7 Refluxo de esgoto | B23: =COUNTIF(Matriz!J$2:J$196,"●")
A24: 8 Tratamento químico | B24: =COUNTIF(Matriz!K$2:K$196,"●")
A25: 9 Contaminação do reservatório | B25: =COUNTIF(Matriz!L$2:L$196,"●")
A26: T Comunicação de crise | B26: =COUNTIF(Matriz!M$2:M$196,"●")
A28: Manutenção por família
A29: Famílias em dia | B29: =COUNTIF(Manutencao!$K$2:$K$17,"Em dia")
A30: Famílias VENCIDAS | B30: =COUNTIF(Manutencao!$K$2:$K$17,"VENCIDO")
A31: Famílias sem registro | B31: =COUNTIF(Manutencao!$K$2:$K$17,"Sem registro")
A33: Autovistoria
A34: Itens VERMELHOS | B34: =COUNTIF(Autovistoria!$I$7:$I$48,"VERMELHO") | C34: Escalar ao síndico agora
A35: Itens AMARELOS | B35: =COUNTIF(Autovistoria!$I$7:$I$48,"AMARELO")
A36: Itens OK | B36: =COUNTIF(Autovistoria!$I$7:$I$48,"OK")
A37: Itens pendentes (sem resposta) | B37: =COUNTIF(Autovistoria!$I$7:$I$48,"Pendente")
A39: Incidentes
A40: Incidentes registrados | B40: =COUNT(Incidentes!$B$2:$B$41)
A41: Incidentes não encerrados | B41: =SUMPRODUCT((Incidentes!$B$2:$B$41<>"")*(Incidentes!$S$2:$S$41<>"Encerrado"))

Sheet Condominio
A1: Ficha do condomínio
A2: Faça uma cópia desta planilha por condomínio e salve no OneDrive. Nunca no GitHub.
A4: Identificação
A5: Nome do condomínio
A6: Administradora
A7: Tipo (escritório / loja / logístico / misto)
A8: Cidade / UF
A9: Nº de pavimentos
A10: Responsável pela ficha
A11: Data do primeiro preenchimento
A12: Data da última revisão
A13: Abastecimento e energia
... A31: Última limpeza de reservatório (data)

Sheet Contatos
A1: Função | B1: Nível de escalonamento | C1: Nome / empresa | D1: Telefone (24h) | E1: E-mail | F1: Observação
A2: Operador de ronda | B2: —
A3: Responsável da manutenção residente | B3: 1
A4: Gestão predial / administradora | B4: 2
A5: Síndico | B5: 3
A6: Fornecedor de tratamento químico (torre, chiller) | B6: Fornecedor
A7: Fornecedor de hidráulica | B7: Fornecedor
A8: Fornecedor de ar-condicionado / chiller | B8: Fornecedor
A9: Fornecedor de bombas e gerador | B9: Fornecedor
A10: Fornecedor de proteção contra incêndio | B10: Fornecedor
A11: Consultor especialista (contratado caso a caso) | B11: Consultor
A12: Laboratório de análise de água | B12: Externo
A13: Caminhão-pipa pré-qualificado | B13: Externo
... A15: Vigilância sanitária local | B15: Externo
A16: SAMU | B16: Externo | D16: 192
A17: Corpo de Bombeiros | B17: Externo | D17: 193
A18: Disque-Intoxicação (confirmar número vigente) | B18: Externo | F18: Anvisa: 0800 722 6001 — conferir se continua vigente antes de usar
A40: Telefones pessoais ficam só nesta ficha (OneDrive), nunca no GitHub. Linhas em branco abaixo da lista são para fornecedores adicionais.

Sheet Catalogo
A1: ID | B1: Grupo | C1: Sistema | D1: O que é / onde está | E1: Como falha ou contamina | F1: Cenários | G1: Ref. | H1: Existe no prédio? (S / N / ?) | I1: Local / observação | J1: Foto ou documento | K1: Data da conferência | L1: Quem informou / fonte | M1: Tratar como | N1: Vistoria | O1: Família
A2: A1 | B2: A. Água potável | C2: Ligação da concessionária | D2: Ramal, cavalete, hidrômetro geral, registros e válvulas na entrada. Pode haver mais de um ramal | E2: Rompimento; falta de água (que gera retrossifonagem); hidrômetro parado; ramal sem retenção quando o prédio abastece direto, sem reservatório | F2: 1,2,4 | G2: ✔ NBR 5626:2020 | M2: =IF(H2="S","Existe",IF(H2="N","Não existe",IF(H2="?","PIOR CASO: tratar como sem proteção","Não preenchido"))) | N2: =IF(H2="?","VISTORIAR",IF(H2="","A PREENCHER","")) | O2: 3
A3: A2 | B3: A. Água potável | C3: Poço artesiano / fonte própria | D3: Captação subterrânea, bomba submersa, selo sanitário, laje de proteção, tratamento, outorga | E3: Contaminação do aquífero (fossa próxima, poço mal selado ou abandonado aberto); falta de outorga e de análise; mistura com a rede da concessionária sem separação | F3: 1,2,3 | G3: ✔ Portaria GM/MS 888/2021 · ✔ NBR 12244:2006 (construção de poço tubular) · ◻ outorga estadual/ANA | M3: =IF(H3="S","Existe",IF(H3="N","Não existe",IF(H3="?","PIOR CASO: tratar como sem proteção","Não preenchido"))) | N3: =IF(H3="?","VISTORIAR",IF(H3="","A PREENCHER","")) | O3: 4
A4: A3 | B4: A. Água potável | C4: Abastecimento emergencial (caminhão-pipa) | D4: Ponto de recebimento de água de terceiros no reservatório | E4: Água de origem desconhecida; tanque do caminhão sujo; mangueira dentro da boca de visita do reservatório (entrada por reservatório); sem cloro | F4: 2,3,9 | G4: ✔ Portaria 888/2021 (abrange abastecimento por carro-pipa) · ◻ cloro mínimo no carro-pipa (0,5 mg/L em fonte secundária) | M4: =IF(H4="S","Existe",IF(H4="N","Não existe",IF(H4="?","PIOR CASO: tratar como sem proteção","Não preenchido"))) | N4: =IF(H4="?","VISTORIAR",IF(H4="","A PREENCHER","")) | O4: 4
A5: A4 | B5: A. Água potável | C5: Reservatório inferior (cisterna) | D5: Tanque enterrado ou no térreo/subsolo, com tampa de inspeção | E5: Infiltração de água do solo ou de poça; tampa sem vedação; ladrão sem proteção; sujeira acumulada; tubulação de esgoto ou pluvial próxima | F5: 2,3,9 | G5: ✔ NBR 5626:2020 | M5: =IF(H5="S","Existe",IF(H5="N","Não existe",IF(H5="?","PIOR CASO: tratar como sem proteção","Não preenchido"))) | N5: =IF(H5="?","VISTORIAR",IF(H5="","A PREENCHER","")) | O5: 1
A6: A5 | B6: A. Água potável | C6: Recalque | D6: Bombas que sobem a água da cisterna ao reservatório superior, boias, quadros | E6: Pane; falta de bomba reserva; retenção falha e a água volta; falta de energia; funcionamento a seco | F6: 2,5 | G6: ✔ NBR 5626:2020 | M6: =IF(H6="S","Existe",IF(H6="N","Não existe",IF(H6="?","PIOR CASO: tratar como sem proteção","Não preenchido"))) | N6: =IF(H6="?","VISTORIAR",IF(H6="","A PREENCHER","")) | O6: 2
A7: A6 | B7: A. Água potável | C7: Reservatório superior (caixa d'água) | D7: Tanques na cobertura (um ou vários, em células, ver A17) | E7: Entrada de sujeira ou água pela tampa e laje; tubulação de outro sistema passando por cima; ladrão sem tela (ver A23); estagnação; água quente do sol | F7: 2,3,9 | G7: ✔ NBR 5626:2020 | M7: =IF(H7="S","Existe",IF(H7="N","Não existe",IF(H7="?","PIOR CASO: tratar como sem proteção","Não preenchido"))) | N7: =IF(H7="?","VISTORIAR",IF(H7="","A PREENCHER","")) | O7: 1
A8: A7 | B8: A. Água potável | C8: Barrilete e colunas | D8: Tubulação que sai do reservatório e distribui às prumadas | E8: Registros sem identificação; interligações improvisadas ("jumper", ver H12); corrosão; registro fechado esquecido | F8: 1,2,4 | G8: ✔ NBR 5626:2020 | M8: =IF(H8="S","Existe",IF(H8="N","Não existe",IF(H8="?","PIOR CASO: tratar como sem proteção","Não preenchido"))) | N8: =IF(H8="?","VISTORIAR",IF(H8="","A PREENCHER","")) | O8: 3
A9: A8 | B9: A. Água potável | C9: Pressurização / redução de pressão | D9: Bombas booster (ver A20), tanque hidropneumático (A19), válvulas redutoras de pressão (VRP) | E9: Pressão alta (rompimento); oscilação; VRP travada aberta ou fechada; bomba com retorno | F9: 4,5 | G9: ✔ NBR 5626:2020 | M9: =IF(H9="S","Existe",IF(H9="N","Não existe",IF(H9="?","PIOR CASO: tratar como sem proteção","Não preenchido"))) | N9: =IF(H9="?","VISTORIAR",IF(H9="","A PREENCHER","")) | O9: 2
A10: A9 | B10: A. Água potável | C10: Rede interna de distribuição | D10: Prumadas, ramais, sub-ramais, registros de andar | E10: Vazamento oculto; trecho morto com água parada; registro não encontrado na emergência | F10: 2,3,4 | G10: ✔ NBR 5626:2020 | M10: =IF(H10="S","Existe",IF(H10="N","Não existe",IF(H10="?","PIOR CASO: tratar como sem proteção","Não preenchido"))) | N10: =IF(H10="?","VISTORIAR",IF(H10="","A PREENCHER","")) | O10: 3
A11: A10 | B11: A. Água potável | C11: Pontos de consumo | D11: Torneiras, copas, bebedouros, lavatórios, chuveiros, vasos, mictórios | E11: Ponto raramente usado estagna; ponto com conexão cruzada; ponto usado como fonte de reposição improvisada | F11: 1,3 | G11: ✔ NBR 5626:2020 | M11: =IF(H11="S","Existe",IF(H11="N","Não existe",IF(H11="?","PIOR CASO: tratar como sem proteção","Não preenchido"))) | N11: =IF(H11="?","VISTORIAR",IF(H11="","A PREENCHER","")) | O11: 3
A12: A11 | B12: A. Água potável | C12: Tratamento pontual de potável (conjunto) | D12: Guarda-chuva dos itens A36 a A39 (filtros, cloração, UV, osmose) | E12: Dosagem errada; filtro saturado; resina contaminada. Marcar o detalhe em A36–A39 | F12: 3 | G12: ✔ Portaria 888/2021 (padrão de potabilidade) | M12: =IF(H12="S","Existe",IF(H12="N","Não existe",IF(H12="?","PIOR CASO: tratar como sem proteção","Não preenchido"))) | N12: =IF(H12="?","VISTORIAR",IF(H12="","A PREENCHER","")) | O12: 4
A13: A12 | B13: A. Água potável | C13: Água quente sanitária (conjunto) | D13: Aquecimento, acumulação, recirculação e trocadores. Detalhe em A24–A31 | E13: Faixa morna favorece Legionella (a faixa de risco varia entre referências, em geral entre ~20 e ~45 °C; confirmar); trocador de parede única contamina; recirculação parada | F13: 1,3 | G13: ✔ NBR 5626:2020 · ✔ ASHRAE 188 · ✔ ASHRAE Guideline 12 | M13: =IF(H13="S","Existe",IF(H13="N","Não existe",IF(H13="?","PIOR CASO: tratar como sem proteção","Não preenchido"))) | N13: =IF(H13="?","VISTORIAR",IF(H13="","A PREENCHER","")) | O13: 5
... A174: G23 | B174: G. Usos especiais | C174: Clínicas, consultórios, estética e pet (autoclave, cadeira odontológica, equipamentos de diálise) | D174: Salas comerciais com equipamentos de saúde ligados à rede do condomínio | E174: Linhas de água de baixa vazão com biofilme; equipamento sem dispositivo antirretorno; descarte de químicos no esgoto | F174: 1,3 | G174: ◻ regulamento sanitário do serviço de saúde (conferir) | M174: =IF(H174="S","Existe",IF(H174="N","Não existe",IF(H174="?","PIOR CASO: tratar como sem proteção","Não preenchido"))) | N174: =IF(H174="?","VISTORIAR",IF(H174="","A PREENCHER","")) | O174: 14
A175: H1 | B175: H. Transversais | C175: Mapa de interconexões entre sistemas | E175: Os dois episódios foram interconexões que ninguém sabia que existiam. Ver a seção "Mapa de interconexões críticas" | F175: 1,T | G175: ◻ — | M175: =IF(H175="S","Existe",IF(H175="N","Não existe",IF(H175="?","PIOR CASO: tratar como sem proteção","Não preenchido"))) | N175: =IF(H175="?","VISTORIAR",IF(H175="","A PREENCHER","")) | O175: 16
A176: H2 | B176: H. Transversais | C176: Identificação e cor das tubulações | E176: Sem isso o operador fecha o registro errado na emergência. A NBR 16783 trata da diferenciação do não potável | F176: 1,T | G176: ✔ NBR 16783:2019 | M176: =IF(H176="S","Existe",IF(H176="N","Não existe",IF(H176="?","PIOR CASO: tratar como sem proteção","Não preenchido"))) | N176: =IF(H176="?","VISTORIAR",IF(H176="","A PREENCHER","")) | O176: 16
A177: H3 | B177: H. Transversais | C177: Mapa e identificação de registros e válvulas de seccionamento | E177: Na emergência, quem fecha o quê e onde; registro sem etiqueta ou escondido em forro | F177: 1,2,4,6 | G177: ◻ — | M177: =IF(H177="S","Existe",IF(H177="N","Não existe",IF(H177="?","PIOR CASO: tratar como sem proteção","Não preenchido"))) | N177: =IF(H177="?","VISTORIAR",IF(H177="","A PREENCHER","")) | O177: 16
A178: H4 | B178: H. Transversais | C178: Medição, sensores e telemetria | E178: Hidrômetro, nível, pressão, cloro, condutividade: o que avisa antes do ocupante | F178: 2,3,4,T | G178: ◻ — | M178: =IF(H178="S","Existe",IF(H178="N","Não existe",IF(H178="?","PIOR CASO: tratar como sem proteção","Não preenchido"))) | N178: =IF(H178="?","VISTORIAR",IF(H178="","A PREENCHER","")) | O178: 16
A179: H5 | B179: H. Transversais | C179: Energia de emergência | E179: Gerador ou no-break para recalque, bombas de incêndio, bombas de drenagem | F179: 2,4,5,6 | G179: ◻ — | M179: =IF(H179="S","Existe",IF(H179="N","Não existe",IF(H179="?","PIOR CASO: tratar como sem proteção","Não preenchido"))) | N179: =IF(H179="?","VISTORIAR",IF(H179="","A PREENCHER","")) | O179: 16
A180: H6 | B180: H. Transversais | C180: Supervisório / BMS / automação | E180: Quem vê o alarme e quem responde; alarme sem destinatário | F180: 5,8,T | G180: ◻ — | M180: =IF(H180="S","Existe",IF(H180="N","Não existe",IF(H180="?","PIOR CASO: tratar como sem proteção","Não preenchido"))) | N180: =IF(H180="?","VISTORIAR",IF(H180="","A PREENCHER","")) | O180: 16
A181: H7 | B181: H. Transversais | C181: Documentação técnica | E181: As-built, memoriais, laudos, ART, PMOC, certificado de limpeza de reservatório | F181: 1,3,T | G181: ✔ Lei 13.589/2018 (PMOC) · ✔ NBR 5674 (gestão de manutenção; ◻ edição vigente: há 2012 e 2024 em fontes) | M181: =IF(H181="S","Existe",IF(H181="N","Não existe",IF(H181="?","PIOR CASO: tratar como sem proteção","Não preenchido"))) | N181: =IF(H181="?","VISTORIAR",IF(H181="","A PREENCHER","")) | O181: 16
A182: H8 | B182: H. Transversais | C182: Responsáveis técnicos e contratos | E182: Quem opera, quem mantém, quem atende na emergência | F182: T | G182: ◻ — | M182: =IF(H182="S","Existe",IF(H182="N","Não existe",IF(H182="?","PIOR CASO: tratar como sem proteção","Não preenchido"))) | N182: =IF(H182="?","VISTORIAR",IF(H182="","A PREENCHER","")) | O182: 16
A183: H9 | B183: H. Transversais | C183: Comunicação de crise | E183: Quem avisa ocupantes, locatários, proprietário, vigilância sanitária, concessionária | F183: T | G183: ◻ — | M183: =IF(H183="S","Existe",IF(H183="N","Não existe",IF(H183="?","PIOR CASO: tratar como sem proteção","Não preenchido"))) | N183: =IF(H183="?","VISTORIAR",IF(H183="","A PREENCHER","")) | O183: 16
A184: H10 | B184: H. Transversais | C184: Segurança de acesso | E184: Espaço confinado (reservatórios), trabalho em altura (cobertura), produto químico | F184: 9,T | G184: ✔ NR-33 · ✔ NR-35 | M184: =IF(H184="S","Existe",IF(H184="N","Não existe",IF(H184="?","PIOR CASO: tratar como sem proteção","Não preenchido"))) | N184: =IF(H184="?","VISTORIAR",IF(H184="","A PREENCHER","")) | O184: 16
A185: H11 | B185: H. Transversais | C185: Válvulas de transferência e interligações previstas entre sistemas | E185: Registro que liga um sistema a outro "para emergência" (RTI ↔ consumo, célula ↔ célula, prédio ↔ prédio, potável ↔ reúso). Previsto, mas sem lacre, sem registro de abertura e sem mapa | F185: 1,2,6 | G185: ◻ — | M185: =IF(H185="S","Existe",IF(H185="N","Não existe",IF(H185="?","PIOR CASO: tratar como sem proteção","Não preenchido"))) | N185: =IF(H185="?","VISTORIAR",IF(H185="","A PREENCHER","")) | O185: 6
A186: H12 | B186: H. Transversais | C186: By-pass improvisado e "jumper" | E186: Tubo, flexível ou mangueira instalado em intervenção e que ficou (a gambiarra que virou definitiva). Ninguém desenhou, ninguém lembra | F186: 1,2 | G186: ◻ — | M186: =IF(H186="S","Existe",IF(H186="N","Não existe",IF(H186="?","PIOR CASO: tratar como sem proteção","Não preenchido"))) | N186: =IF(H186="?","VISTORIAR",IF(H186="","A PREENCHER","")) | O186: 6
... A196: H22 | B196: H. Transversais | C196: Relatório mensal e checklist dos fornecedores (via administradora) | E196: Relatório que já existe + checklist padrão do projeto; cadência semanal pedida nos itens críticos | F196: 3,8,T | G196: ◻ — | M196: =IF(H196="S","Existe",IF(H196="N","Não existe",IF(H196="?","PIOR CASO: tratar como sem proteção","Não preenchido"))) | N196: =IF(H196="?","VISTORIAR",IF(H196="","A PREENCHER","")) | O196: 16

Sheet Matriz
A1: ID | B1: Sistema | C1: Existe? | D1: 1 | E1: 2 | F1: 3 | G1: 4 | H1: 5 | I1: 6 | J1: 7 | K1: 8 | L1: 9 | M1: T
A2: =Catalogo!A2 | B2: =Catalogo!C2 | C2: =IF(Catalogo!H2="","(vazio)",Catalogo!H2) | D2: =IF(AND(ISNUMBER(SEARCH(","&D$1&",",","&SUBSTITUTE(Catalogo!$F2," ","")&",")),Catalogo!$H2<>"N"),"●","") | E2: =IF(AND(ISNUMBER(SEARCH(","&E$1&",",","&SUBSTITUTE(Catalogo!$F2," ","")&",")),Catalogo!$H2<>"N"),"●","") | F2: =IF(AND(ISNUMBER(SEARCH(","&F$1&",",","&SUBSTITUTE(Catalogo!$F2," ","")&",")),Catalogo!$H2<>"N"),"●","") | G2: =IF(AND(ISNUMBER(SEARCH(","&G$1&",",","&SUBSTITUTE(Catalogo!$F2," ","")&",")),Catalogo!$H2<>"N"),"●","") | H2: =IF(AND(ISNUMBER(SEARCH(","&H$1&",",","&SUBSTITUTE(Catalogo!$F2," ","")&",")),Catalogo!$H2<>"N"),"●","") | I2: =IF(AND(ISNUMBER(SEARCH(","&I$1&",",","&SUBSTITUTE(Catalogo!$F2," ","")&",")),Catalogo!$H2<>"N"),"●","") | J2: =IF(AND(ISNUMBER(SEARCH(","&J$1&",",","&SUBSTITUTE(Catalogo!$F2," ","")&",")),Catalogo!$H2<>"N"),"●","") | K2: =IF(AND(ISNUMBER(SEARCH(","&K$1&",",","&SUBSTITUTE(Catalogo!$F2," ","")&",")),Catalogo!$H2<>"N"),"●","") | ... M2: =IF(AND(ISNUMBER(SEARCH(","&M$1&",",","&SUBSTITUTE(Catalogo!$F2," ","")&",")),Catalogo!$H2<>"N"),"●","")
A3: =Catalogo!A3 | B3: =Catalogo!C3 | C3: =IF(Catalogo!H3="","(vazio)",Catalogo!H3) | D3: =IF(AND(ISNUMBER(SEARCH(","&D$1&",",","&SUBSTITUTE(Catalogo!$F3," ","")&",")),Catalogo!$H3<>"N"),"●","") | E3: =IF(AND(ISNUMBER(SEARCH(","&E$1&",",","&SUBSTITUTE(Catalogo!$F3," ","")&",")),Catalogo!$H3<>"N"),"●","") | F3: =IF(AND(ISNUMBER(SEARCH(","&F$1&",",","&SUBSTITUTE(Catalogo!$F3," ","")&",")),Catalogo!$H3<>"N"),"●","") | G3: =IF(AND(ISNUMBER(SEARCH(","&G$1&",",","&SUBSTITUTE(Catalogo!$F3," ","")&",")),Catalogo!$H3<>"N"),"●","") | H3: =IF(AND(ISNUMBER(SEARCH(","&H$1&",",","&SUBSTITUTE(Catalogo!$F3," ","")&",")),Catalogo!$H3<>"N"),"●","") | I3: =IF(AND(ISNUMBER(SEARCH(","&I$1&",",","&SUBSTITUTE(Catalogo!$F3," ","")&",")),Catalogo!$H3<>"N"),"●","") | J3: =IF(AND(ISNUMBER(SEARCH(","&J$1&",",","&SUBSTITUTE(Catalogo!$F3," ","")&",")),Catalogo!$H3<>"N"),"●","") | K3: =IF(AND(ISNUMBER(SEARCH(","&K$1&",",","&SUBSTITUTE(Catalogo!$F3," ","")&",")),Catalogo!$H3<>"N"),"●","") | ... M3: =IF(AND(ISNUMBER(SEARCH(","&M$1&",",","&SUBSTITUTE(Catalogo!$F3," ","")&",")),Catalogo!$H3<>"N"),"●","")
A4: =Catalogo!A4 | B4: =Catalogo!C4 | C4: =IF(Catalogo!H4="","(vazio)",Catalogo!H4) | D4: =IF(AND(ISNUMBER(SEARCH(","&D$1&",",","&SUBSTITUTE(Catalogo!$F4," ","")&",")),Catalogo!$H4<>"N"),"●","") | E4: =IF(AND(ISNUMBER(SEARCH(","&E$1&",",","&SUBSTITUTE(Catalogo!$F4," ","")&",")),Catalogo!$H4<>"N"),"●","") | F4: =IF(AND(ISNUMBER(SEARCH(","&F$1&",",","&SUBSTITUTE(Catalogo!$F4," ","")&",")),Catalogo!$H4<>"N"),"●","") | G4: =IF(AND(ISNUMBER(SEARCH(","&G$1&",",","&SUBSTITUTE(Catalogo!$F4," ","")&",")),Catalogo!$H4<>"N"),"●","") | H4: =IF(AND(ISNUMBER(SEARCH(","&H$1&",",","&SUBSTITUTE(Catalogo!$F4," ","")&",")),Catalogo!$H4<>"N"),"●","") | I4: =IF(AND(ISNUMBER(SEARCH(","&I$1&",",","&SUBSTITUTE(Catalogo!$F4," ","")&",")),Catalogo!$H4<>"N"),"●","") | J4: =IF(AND(ISNUMBER(SEARCH(","&J$1&",",","&SUBSTITUTE(Catalogo!$F4," ","")&",")),Catalogo!$H4<>"N"),"●","") | K4: =IF(AND(ISNUMBER(SEARCH(","&K$1&",",","&SUBSTITUTE(Catalogo!$F4," ","")&",")),Catalogo!$H4<>"N"),"●","") | ... M4: =IF(AND(ISNUMBER(SEARCH(","&M$1&",",","&SUBSTITUTE(Catalogo!$F4," ","")&",")),Catalogo!$H4<>"N"),"●","")
A5: =Catalogo!A5 | B5: =Catalogo!C5 | C5: =IF(Catalogo!H5="","(vazio)",Catalogo!H5) | D5: =IF(AND(ISNUMBER(SEARCH(","&D$1&",",","&SUBSTITUTE(Catalogo!$F5," ","")&",")),Catalogo!$H5<>"N"),"●","") | E5: =IF(AND(ISNUMBER(SEARCH(","&E$1&",",","&SUBSTITUTE(Catalogo!$F5," ","")&",")),Catalogo!$H5<>"N"),"●","") | F5: =IF(AND(ISNUMBER(SEARCH(","&F$1&",",","&SUBSTITUTE(Catalogo!$F5," ","")&",")),Catalogo!$H5<>"N"),"●","") | G5: =IF(AND(ISNUMBER(SEARCH(","&G$1&",",","&SUBSTITUTE(Catalogo!$F5," ","")&",")),Catalogo!$H5<>"N"),"●","") | H5: =IF(AND(ISNUMBER(SEARCH(","&H$1&",",","&SUBSTITUTE(Catalogo!$F5," ","")&",")),Catalogo!$H5<>"N"),"●","") | I5: =IF(AND(ISNUMBER(SEARCH(","&I$1&",",","&SUBSTITUTE(Catalogo!$F5," ","")&",")),Catalogo!$H5<>"N"),"●","") | J5: =IF(AND(ISNUMBER(SEARCH(","&J$1&",",","&SUBSTITUTE(Catalogo!$F5," ","")&",")),Catalogo!$H5<>"N"),"●","") | K5: =IF(AND(ISNUMBER(SEARCH(","&K$1&",",","&SUBSTITUTE(Catalogo!$F5," ","")&",")),Catalogo!$H5<>"N"),"●","") | ... M5: =IF(AND(ISNUMBER(SEARCH(","&M$1&",",","&SUBSTITUTE(Catalogo!$F5," ","")&",")),Catalogo!$H5<>"N"),"●","")
A6: =Catalogo!A6 | B6: =Catalogo!C6 | C6: =IF(Catalogo!H6="","(vazio)",Catalogo!H6) | D6: =IF(AND(ISNUMBER(SEARCH(","&D$1&",",","&SUBSTITUTE(Catalogo!$F6," ","")&",")),Catalogo!$H6<>"N"),"●","") | E6: =IF(AND(ISNUMBER(SEARCH(","&E$1&",",","&SUBSTITUTE(Catalogo!$F6," ","")&",")),Catalogo!$H6<>"N"),"●","") | F6: =IF(AND(ISNUMBER(SEARCH(","&F$1&",",","&SUBSTITUTE(Catalogo!$F6," ","")&",")),Catalogo!$H6<>"N"),"●","") | G6: =IF(AND(ISNUMBER(SEARCH(","&G$1&",",","&SUBSTITUTE(Catalogo!$F6," ","")&",")),Catalogo!$H6<>"N"),"●","") | H6: =IF(AND(ISNUMBER(SEARCH(","&H$1&",",","&SUBSTITUTE(Catalogo!$F6," ","")&",")),Catalogo!$H6<>"N"),"●","") | I6: =IF(AND(ISNUMBER(SEARCH(","&I$1&",",","&SUBSTITUTE(Catalogo!$F6," ","")&",")),Catalogo!$H6<>"N"),"●","") | J6: =IF(AND(ISNUMBER(SEARCH(","&J$1&",",","&SUBSTITUTE(Catalogo!$F6," ","")&",")),Catalogo!$H6<>"N"),"●","") | K6: =IF(AND(ISNUMBER(SEARCH(","&K$1&",",","&SUBSTITUTE(Catalogo!$F6," ","")&",")),Catalogo!$H6<>"N"),"●","") | ... M6: =IF(AND(ISNUMBER(SEARCH(","&M$1&",",","&SUBSTITUTE(Catalogo!$F6," ","")&",")),Catalogo!$H6<>"N"),"●","")
A7: =Catalogo!A7 | B7: =Catalogo!C7 | C7: =IF(Catalogo!H7="","(vazio)",Catalogo!H7) | D7: =IF(AND(ISNUMBER(SEARCH(","&D$1&",",","&SUBSTITUTE(Catalogo!$F7," ","")&",")),Catalogo!$H7<>"N"),"●","") | E7: =IF(AND(ISNUMBER(SEARCH(","&E$1&",",","&SUBSTITUTE(Catalogo!$F7," ","")&",")),Catalogo!$H7<>"N"),"●","") | F7: =IF(AND(ISNUMBER(SEARCH(","&F$1&",",","&SUBSTITUTE(Catalogo!$F7," ","")&",")),Catalogo!$H7<>"N"),"●","") | G7: =IF(AND(ISNUMBER(SEARCH(","&G$1&",",","&SUBSTITUTE(Catalogo!$F7," ","")&",")),Catalogo!$H7<>"N"),"●","") | H7: =IF(AND(ISNUMBER(SEARCH(","&H$1&",",","&SUBSTITUTE(Catalogo!$F7," ","")&",")),Catalogo!$H7<>"N"),"●","") | I7: =IF(AND(ISNUMBER(SEARCH(","&I$1&",",","&SUBSTITUTE(Catalogo!$F7," ","")&",")),Catalogo!$H7<>"N"),"●","") | J7: =IF(AND(ISNUMBER(SEARCH(","&J$1&",",","&SUBSTITUTE(Catalogo!$F7," ","")&",")),Catalogo!$H7<>"N"),"●","") | K7: =IF(AND(ISNUMBER(SEARCH(","&K$1&",",","&SUBSTITUTE(Catalogo!$F7," ","")&",")),Catalogo!$H7<>"N"),"●","") | ... M7: =IF(AND(ISNUMBER(SEARCH(","&M$1&",",","&SUBSTITUTE(Catalogo!$F7," ","")&",")),Catalogo!$H7<>"N"),"●","")
A8: =Catalogo!A8 | B8: =Catalogo!C8 | C8: =IF(Catalogo!H8="","(vazio)",Catalogo!H8) | D8: =IF(AND(ISNUMBER(SEARCH(","&D$1&",",","&SUBSTITUTE(Catalogo!$F8," ","")&",")),Catalogo!$H8<>"N"),"●","") | E8: =IF(AND(ISNUMBER(SEARCH(","&E$1&",",","&SUBSTITUTE(Catalogo!$F8," ","")&",")),Catalogo!$H8<>"N"),"●","") | F8: =IF(AND(ISNUMBER(SEARCH(","&F$1&",",","&SUBSTITUTE(Catalogo!$F8," ","")&",")),Catalogo!$H8<>"N"),"●","") | G8: =IF(AND(ISNUMBER(SEARCH(","&G$1&",",","&SUBSTITUTE(Catalogo!$F8," ","")&",")),Catalogo!$H8<>"N"),"●","") | H8: =IF(AND(ISNUMBER(SEARCH(","&H$1&",",","&SUBSTITUTE(Catalogo!$F8," ","")&",")),Catalogo!$H8<>"N"),"●","") | I8: =IF(AND(ISNUMBER(SEARCH(","&I$1&",",","&SUBSTITUTE(Catalogo!$F8," ","")&",")),Catalogo!$H8<>"N"),"●","") | J8: =IF(AND(ISNUMBER(SEARCH(","&J$1&",",","&SUBSTITUTE(Catalogo!$F8," ","")&",")),Catalogo!$H8<>"N"),"●","") | K8: =IF(AND(ISNUMBER(SEARCH(","&K$1&",",","&SUBSTITUTE(Catalogo!$F8," ","")&",")),Catalogo!$H8<>"N"),"●","") | ... M8: =IF(AND(ISNUMBER(SEARCH(","&M$1&",",","&SUBSTITUTE(Catalogo!$F8," ","")&",")),Catalogo!$H8<>"N"),"●","")
A9: =Catalogo!A9 | B9: =Catalogo!C9 | C9: =IF(Catalogo!H9="","(vazio)",Catalogo!H9) | D9: =IF(AND(ISNUMBER(SEARCH(","&D$1&",",","&SUBSTITUTE(Catalogo!$F9," ","")&",")),Catalogo!$H9<>"N"),"●","") | E9: =IF(AND(ISNUMBER(SEARCH(","&E$1&",",","&SUBSTITUTE(Catalogo!$F9," ","")&",")),Catalogo!$H9<>"N"),"●","") | F9: =IF(AND(ISNUMBER(SEARCH(","&F$1&",",","&SUBSTITUTE(Catalogo!$F9," ","")&",")),Catalogo!$H9<>"N"),"●","") | G9: =IF(AND(ISNUMBER(SEARCH(","&G$1&",",","&SUBSTITUTE(Catalogo!$F9," ","")&",")),Catalogo!$H9<>"N"),"●","") | H9: =IF(AND(ISNUMBER(SEARCH(","&H$1&",",","&SUBSTITUTE(Catalogo!$F9," ","")&",")),Catalogo!$H9<>"N"),"●","") | I9: =IF(AND(ISNUMBER(SEARCH(","&I$1&",",","&SUBSTITUTE(Catalogo!$F9," ","")&",")),Catalogo!$H9<>"N"),"●","") | J9: =IF(AND(ISNUMBER(SEARCH(","&J$1&",",","&SUBSTITUTE(Catalogo!$F9," ","")&",")),Catalogo!$H9<>"N"),"●","") | K9: =IF(AND(ISNUMBER(SEARCH(","&K$1&",",","&SUBSTITUTE(Catalogo!$F9," ","")&",")),Catalogo!$H9<>"N"),"●","") | ... M9: =IF(AND(ISNUMBER(SEARCH(","&M$1&",",","&SUBSTITUTE(Catalogo!$F9," ","")&",")),Catalogo!$H9<>"N"),"●","")
A10: =Catalogo!A10 | B10: =Catalogo!C10 | C10: =IF(Catalogo!H10="","(vazio)",Catalogo!H10) | D10: =IF(AND(ISNUMBER(SEARCH(","&D$1&",",","&SUBSTITUTE(Catalogo!$F10," ","")&",")),Catalogo!$H10<>"N"),"●","") | E10: =IF(AND(ISNUMBER(SEARCH(","&E$1&",",","&SUBSTITUTE(Catalogo!$F10," ","")&",")),Catalogo!$H10<>"N"),"●","") | F10: =IF(AND(ISNUMBER(SEARCH(","&F$1&",",","&SUBSTITUTE(Catalogo!$F10," ","")&",")),Catalogo!$H10<>"N"),"●","") | G10: =IF(AND(ISNUMBER(SEARCH(","&G$1&",",","&SUBSTITUTE(Catalogo!$F10," ","")&",")),Catalogo!$H10<>"N"),"●","") | H10: =IF(AND(ISNUMBER(SEARCH(","&H$1&",",","&SUBSTITUTE(Catalogo!$F10," ","")&",")),Catalogo!$H10<>"N"),"●","") | I10: =IF(AND(ISNUMBER(SEARCH(","&I$1&",",","&SUBSTITUTE(Catalogo!$F10," ","")&",")),Catalogo!$H10<>"N"),"●","") | J10: =IF(AND(ISNUMBER(SEARCH(","&J$1&",",","&SUBSTITUTE(Catalogo!$F10," ","")&",")),Catalogo!$H10<>"N"),"●","") | K10: =IF(AND(ISNUMBER(SEARCH(","&K$1&",",","&SUBSTITUTE(Catalogo!$F10," ","")&",")),Catalogo!$H10<>"N"),"●","") | ... M10: =IF(AND(ISNUMBER(SEARCH(","&M$1&",",","&SUBSTITUTE(Catalogo!$F10," ","")&",")),Catalogo!$H10<>"N"),"●","")
A11: =Catalogo!A11 | B11: =Catalogo!C11 | C11: =IF(Catalogo!H11="","(vazio)",Catalogo!H11) | D11: =IF(AND(ISNUMBER(SEARCH(","&D$1&",",","&SUBSTITUTE(Catalogo!$F11," ","")&",")),Catalogo!$H11<>"N"),"●","") | E11: =IF(AND(ISNUMBER(SEARCH(","&E$1&",",","&SUBSTITUTE(Catalogo!$F11," ","")&",")),Catalogo!$H11<>"N"),"●","") | F11: =IF(AND(ISNUMBER(SEARCH(","&F$1&",",","&SUBSTITUTE(Catalogo!$F11," ","")&",")),Catalogo!$H11<>"N"),"●","") | G11: =IF(AND(ISNUMBER(SEARCH(","&G$1&",",","&SUBSTITUTE(Catalogo!$F11," ","")&",")),Catalogo!$H11<>"N"),"●","") | H11: =IF(AND(ISNUMBER(SEARCH(","&H$1&",",","&SUBSTITUTE(Catalogo!$F11," ","")&",")),Catalogo!$H11<>"N"),"●","") | I11: =IF(AND(ISNUMBER(SEARCH(","&I$1&",",","&SUBSTITUTE(Catalogo!$F11," ","")&",")),Catalogo!$H11<>"N"),"●","") | J11: =IF(AND(ISNUMBER(SEARCH(","&J$1&",",","&SUBSTITUTE(Catalogo!$F11," ","")&",")),Catalogo!$H11<>"N"),"●","") | K11: =IF(AND(ISNUMBER(SEARCH(","&K$1&",",","&SUBSTITUTE(Catalogo!$F11," ","")&",")),Catalogo!$H11<>"N"),"●","") | ... M11: =IF(AND(ISNUMBER(SEARCH(","&M$1&",",","&SUBSTITUTE(Catalogo!$F11," ","")&",")),Catalogo!$H11<>"N"),"●","")
A12: =Catalogo!A12 | B12: =Catalogo!C12 | C12: =IF(Catalogo!H12="","(vazio)",Catalogo!H12) | D12: =IF(AND(ISNUMBER(SEARCH(","&D$1&",",","&SUBSTITUTE(Catalogo!$F12," ","")&",")),Catalogo!$H12<>"N"),"●","") | E12: =IF(AND(ISNUMBER(SEARCH(","&E$1&",",","&SUBSTITUTE(Catalogo!$F12," ","")&",")),Catalogo!$H12<>"N"),"●","") | F12: =IF(AND(ISNUMBER(SEARCH(","&F$1&",",","&SUBSTITUTE(Catalogo!$F12," ","")&",")),Catalogo!$H12<>"N"),"●","") | G12: =IF(AND(ISNUMBER(SEARCH(","&G$1&",",","&SUBSTITUTE(Catalogo!$F12," ","")&",")),Catalogo!$H12<>"N"),"●","") | H12: =IF(AND(ISNUMBER(SEARCH(","&H$1&",",","&SUBSTITUTE(Catalogo!$F12," ","")&",")),Catalogo!$H12<>"N"),"●","") | I12: =IF(AND(ISNUMBER(SEARCH(","&I$1&",",","&SUBSTITUTE(Catalogo!$F12," ","")&",")),Catalogo!$H12<>"N"),"●","") | J12: =IF(AND(ISNUMBER(SEARCH(","&J$1&",",","&SUBSTITUTE(Catalogo!$F12," ","")&",")),Catalogo!$H12<>"N"),"●","") | K12: =IF(AND(ISNUMBER(SEARCH(","&K$1&",",","&SUBSTITUTE(Catalogo!$F12," ","")&",")),Catalogo!$H12<>"N"),"●","") | ... M12: =IF(AND(ISNUMBER(SEARCH(","&M$1&",",","&SUBSTITUTE(Catalogo!$F12," ","")&",")),Catalogo!$H12<>"N"),"●","")
A13: =Catalogo!A13 | B13: =Catalogo!C13 | C13: =IF(Catalogo!H13="","(vazio)",Catalogo!H13) | D13: =IF(AND(ISNUMBER(SEARCH(","&D$1&",",","&SUBSTITUTE(Catalogo!$F13," ","")&",")),Catalogo!$H13<>"N"),"●","") | E13: =IF(AND(ISNUMBER(SEARCH(","&E$1&",",","&SUBSTITUTE(Catalogo!$F13," ","")&",")),Catalogo!$H13<>"N"),"●","") | F13: =IF(AND(ISNUMBER(SEARCH(","&F$1&",",","&SUBSTITUTE(Catalogo!$F13," ","")&",")),Catalogo!$H13<>"N"),"●","") | G13: =IF(AND(ISNUMBER(SEARCH(","&G$1&",",","&SUBSTITUTE(Catalogo!$F13," ","")&",")),Catalogo!$H13<>"N"),"●","") | H13: =IF(AND(ISNUMBER(SEARCH(","&H$1&",",","&SUBSTITUTE(Catalogo!$F13," ","")&",")),Catalogo!$H13<>"N"),"●","") | I13: =IF(AND(ISNUMBER(SEARCH(","&I$1&",",","&SUBSTITUTE(Catalogo!$F13," ","")&",")),Catalogo!$H13<>"N"),"●","") | J13: =IF(AND(ISNUMBER(SEARCH(","&J$1&",",","&SUBSTITUTE(Catalogo!$F13," ","")&",")),Catalogo!$H13<>"N"),"●","") | K13: =IF(AND(ISNUMBER(SEARCH(","&K$1&",",","&SUBSTITUTE(Catalogo!$F13," ","")&",")),Catalogo!$H13<>"N"),"●","") | ... M13: =IF(AND(ISNUMBER(SEARCH(","&M$1&",",","&SUBSTITUTE(Catalogo!$F13," ","")&",")),Catalogo!$H13<>"N"),"●","")
... A196: =Catalogo!A196 | B196: =Catalogo!C196 | C196: =IF(Catalogo!H196="","(vazio)",Catalogo!H196) | D196: =IF(AND(ISNUMBER(SEARCH(","&D$1&",",","&SUBSTITUTE(Catalogo!$F196," ","")&",")),Catalogo!$H196<>"N"),"●","") | E196: =IF(AND(ISNUMBER(SEARCH(","&E$1&",",","&SUBSTITUTE(Catalogo!$F196," ","")&",")),Catalogo!$H196<>"N"),"●","") | F196: =IF(AND(ISNUMBER(SEARCH(","&F$1&",",","&SUBSTITUTE(Catalogo!$F196," ","")&",")),Catalogo!$H196<>"N"),"●","") | G196: =IF(AND(ISNUMBER(SEARCH(","&G$1&",",","&SUBSTITUTE(Catalogo!$F196," ","")&",")),Catalogo!$H196<>"N"),"●","") | H196: =IF(AND(ISNUMBER(SEARCH(","&H$1&",",","&SUBSTITUTE(Catalogo!$F196," ","")&",")),Catalogo!$H196<>"N"),"●","") | I196: =IF(AND(ISNUMBER(SEARCH(","&I$1&",",","&SUBSTITUTE(Catalogo!$F196," ","")&",")),Catalogo!$H196<>"N"),"●","") | J196: =IF(AND(ISNUMBER(SEARCH(","&J$1&",",","&SUBSTITUTE(Catalogo!$F196," ","")&",")),Catalogo!$H196<>"N"),"●","") | K196: =IF(AND(ISNUMBER(SEARCH(","&K$1&",",","&SUBSTITUTE(Catalogo!$F196," ","")&",")),Catalogo!$H196<>"N"),"●","") | ... M196: =IF(AND(ISNUMBER(SEARCH(","&M$1&",",","&SUBSTITUTE(Catalogo!$F196," ","")&",")),Catalogo!$H196<>"N"),"●","")
B198: Total de itens aplicáveis por cenário: | D198: =COUNTIF(D2:D196,"●") | E198: =COUNTIF(E2:E196,"●") | F198: =COUNTIF(F2:F196,"●") | G198: =COUNTIF(G2:G196,"●") | H198: =COUNTIF(H2:H196,"●") | I198: =COUNTIF(I2:I196,"●") | J198: =COUNTIF(J2:J196,"●") | K198: =COUNTIF(K2:K196,"●") | ... M198: =COUNTIF(M2:M196,"●")
B199: ● = o item entra no cenário e NÃO foi marcado N. Item em branco ou '?' entra (pior caso). Cenários: 1 contaminação cruzada, 2 falta de água, 3 água fora do padrão, 4 vazamento/alagamento, 5 falha de bomba/energia, 6 incêndio, 7 refluxo de esgoto, 8 tratamento químico, 9 contaminação do reservatório, T comunicação de crise.

Sheet Manutencao
A1: Nº | B1: Família | C1: IDs (catálogo) | D1: O que se mantém | E1: Cadência de referência (catálogo) | F1: Itens aplicáveis na ficha | G1: Responsável (fornecedor) | H1: Periodicidade (dias) | I1: Última execução | J1: Próxima | K1: Status | L1: Evidência (documento / OS) | M1: Observação
A2: 1 | B2: Reservatórios e armazenamento de potável | C2: A4, A6, A17, A18, A22, A23 | D2: Limpeza e desinfecção, inspeção de tampa, vedação, ladrão, respiro, tela, boias e sensores; ensaio de estanqueidade | E2: Nível: semanal (pedido). Limpeza: periodicidade a definir (ver RDC 216 para restaurantes, ◻) | F2: =COUNTIFS(Catalogo!$O$2:$O$196,A2,Catalogo!$H$2:$H$196,"<>N") | J2: =IF(OR(H2="",I2=""),"",I2+H2) | K2: =IF(F2=0,"Sem itens",IF(OR(H2="",I2=""),"Sem registro",IF(TODAY()>J2,"VENCIDO","Em dia")))
A3: 2 | B3: Bombas e pressurização | C3: A5, A8, A19, A20, A21 | D3: Revezamento de bombas, vedação, rolamento, quadro, inversor, vaso hidropneumático, VRP, válvulas de alívio | E3: Teste de revezamento: a definir | F3: =COUNTIFS(Catalogo!$O$2:$O$196,A3,Catalogo!$H$2:$H$196,"<>N") | J3: =IF(OR(H3="",I3=""),"",I3+H3) | K3: =IF(F3=0,"Sem itens",IF(OR(H3="",I3=""),"Sem registro",IF(TODAY()>J3,"VENCIDO","Em dia")))
A4: 3 | B4: Rede e pontos de consumo | C4: A1, A7, A9, A10, A15, A16, A32, A33, A34, A35, A40, A41, A42, A43, G10, G11 | D4: Descarga de pontos pouco usados, manutenção de torneiras e válvulas, hidrômetros, registros, pontos de mangueira, ramais de locatário | E4: Torneira sentinela: ronda (pedido) | F4: =COUNTIFS(Catalogo!$O$2:$O$196,A4,Catalogo!$H$2:$H$196,"<>N") | J4: =IF(OR(H4="",I4=""),"",I4+H4) | K4: =IF(F4=0,"Sem itens",IF(OR(H4="",I4=""),"Sem registro",IF(TODAY()>J4,"VENCIDO","Em dia")))
A5: 4 | B5: Tratamento de potável e qualidade | C5: A2, A3, A11, A14, A36, A37, A38, A39 | D5: Dosagem, residual, troca de filtro e lâmpada UV, análise laboratorial, controle de poço e carro-pipa | E5: Cloro residual: semanal (pedido) | F5: =COUNTIFS(Catalogo!$O$2:$O$196,A5,Catalogo!$H$2:$H$196,"<>N") | J5: =IF(OR(H5="",I5=""),"",I5+H5) | K5: =IF(F5=0,"Sem itens",IF(OR(H5="",I5=""),"Sem registro",IF(TODAY()>J5,"VENCIDO","Em dia")))
A6: 5 | B6: Água quente | C6: A12, A24, A25, A26, A27, A28, A29, A30, A31, G12 | D6: Temperatura de acumulação e de retorno, recirculação, válvulas misturadoras, T&P, trocadores, limpeza de acumulador | E6: Temperaturas: a definir (ASHRAE Guideline 12, ◻) | F6: =COUNTIFS(Catalogo!$O$2:$O$196,A6,Catalogo!$H$2:$H$196,"<>N") | J6: =IF(OR(H6="",I6=""),"",I6+H6) | K6: =IF(F6=0,"Sem itens",IF(OR(H6="",I6=""),"Sem registro",IF(TODAY()>J6,"VENCIDO","Em dia")))
A7: 6 | B7: Reposição, refluxo e interligações | C7: A13, C3, C14, C15, C16, C17, C18, C19, C20, H11, H12, H13, H14, H15, H17 | D7: Ensaio de BPV e retenção; inspeção de folga de ar; busca de mangueira, jumper e by-pass; indicador de reposição | E7: Reposição de água do circuito: semanal (pedido) | F7: =COUNTIFS(Catalogo!$O$2:$O$196,A7,Catalogo!$H$2:$H$196,"<>N") | J7: =IF(OR(H7="",I7=""),"",I7+H7) | K7: =IF(F7=0,"Sem itens",IF(OR(H7="",I7=""),"Sem registro",IF(TODAY()>J7,"VENCIDO","Em dia")))
A8: 7 | B8: Reúso e fontes alternativas | C8: B1, B2, B3, B4, B5, B6, B7, B8, B9, B10, B11, B12, B13, B14, B15, B16 | D8: Controle de qualidade do reúso, limpeza de cisterna, first flush, filtros, identificação, ensaio de estanqueidade da separação potável × reúso | E8: A definir pela NBR 16783 (◻) | F8: =COUNTIFS(Catalogo!$O$2:$O$196,A8,Catalogo!$H$2:$H$196,"<>N") | J8: =IF(OR(H8="",I8=""),"",I8+H8) | K8: =IF(F8=0,"Sem itens",IF(OR(H8="",I8=""),"Sem registro",IF(TODAY()>J8,"VENCIDO","Em dia")))
A9: 8 | B9: Circuitos de climatização | C9: C1, C4, C5, C6, C7, C9, C11, C12, C13, C21, C22, C23, C24, C25, C33, C36, C37 | D9: Pressão, vazamento, bombas, trocadores, glicol, vaso de expansão, drenos e bandejas, PMOC | E9: PMOC (Lei 13.589); reposição: ver família 6 | F9: =COUNTIFS(Catalogo!$O$2:$O$196,A9,Catalogo!$H$2:$H$196,"<>N") | J9: =IF(OR(H9="",I9=""),"",I9+H9) | K9: =IF(F9=0,"Sem itens",IF(OR(H9="",I9=""),"Sem registro",IF(TODAY()>J9,"VENCIDO","Em dia")))
A10: 9 | B10: Torre de resfriamento e tratamento químico | C10: C2, C8, C10, C26, C27, C28, C29, C30, C31, C32, C34, C35, C38 | D10: Limpeza e desinfecção de bacia, enchimento, biocida, condutividade, purga, controlador, sondas, produto químico e contenção | E10: Dosagem química: semanal (pedido) | F10: =COUNTIFS(Catalogo!$O$2:$O$196,A10,Catalogo!$H$2:$H$196,"<>N") | J10: =IF(OR(H10="",I10=""),"",I10+H10) | K10: =IF(F10=0,"Sem itens",IF(OR(H10="",I10=""),"Sem registro",IF(TODAY()>J10,"VENCIDO","Em dia")))
A11: 10 | B11: Incêndio | C11: D1 a D21 | D11: Teste de bombas (principal, jockey, diesel), válvulas supervisionadas abertas, mangueiras, hidrantes, RTI, rede seca, teste do ponto de teste | E11: Teste de bomba de incêndio: semanal (pedido) | F11: =COUNTIFS(Catalogo!$O$2:$O$196,A11,Catalogo!$H$2:$H$196,"<>N") | J11: =IF(OR(H11="",I11=""),"",I11+H11) | K11: =IF(F11=0,"Sem itens",IF(OR(H11="",I11=""),"Sem registro",IF(TODAY()>J11,"VENCIDO","Em dia")))
A12: 11 | B12: Esgoto e drenagem | C12: E1 a E24 | D12: Limpeza de caixas, gordura, poços, bombas de recalque e de drenagem, ralos e selos, válvulas de retenção, reservatório de detenção | E12: Alarme de nível das bombas: a definir | F12: =COUNTIFS(Catalogo!$O$2:$O$196,A12,Catalogo!$H$2:$H$196,"<>N") | J12: =IF(OR(H12="",I12=""),"",I12+H12) | K12: =IF(F12=0,"Sem itens",IF(OR(H12="",I12=""),"Sem registro",IF(TODAY()>J12,"VENCIDO","Em dia")))
A13: 12 | B13: ETA, ETE e efluentes | C13: F1 a F8 | D13: Operação e registro de ETA/ETE, sopradores, membranas, lodo, terciário, fossa, lavagem | E13: Licença e laudos: a definir (CONAMA 430, ◻ regra estadual) | F13: =COUNTIFS(Catalogo!$O$2:$O$196,A13,Catalogo!$H$2:$H$196,"<>N") | J13: =IF(OR(H13="",I13=""),"",I13+H13) | K13: =IF(F13=0,"Sem itens",IF(OR(H13="",I13=""),"Sem registro",IF(TODAY()>J13,"VENCIDO","Em dia")))
... A17: 16 | B17: Outros e gestão | C17: G3, G9, G13, G14, G15, G22, H1 a H10, H16, H18, H19, H20, H21, H22 | D17: Irrigação, nebulização, telhado verde, lavagem, eventos; mapa, registros, telemetria, energia, documentação, contratos, comunicação, treinamento | E17: Relatório mensal + cadência semanal dos itens críticos | F17: =COUNTIFS(Catalogo!$O$2:$O$196,A17,Catalogo!$H$2:$H$196,"<>N") | J17: =IF(OR(H17="",I17=""),"",I17+H17) | K17: =IF(F17=0,"Sem itens",IF(OR(H17="",I17=""),"Sem registro",IF(TODAY()>J17,"VENCIDO","Em dia")))
B19: A cadência de referência vem do catálogo: só o que o projeto pede (semanal nos itens críticos) ou o que a fonte conferida diz. As demais periodicidades dependem do responsável técnico, do contrato e da regra local: preencha a coluna H com o que o condomínio adota. Sem periodicidade e data de execução, o status é 'Sem registro'.

Sheet Autovistoria
A1: Autovistoria — pontos de contaminação cruzada (Cenário 1)
A2: Data da autovistoria | G2: S = sim · N = não · ? = não sei (vale como pior caso) · NA = não se aplica. Fotografe cada ponto. Só olhe e registre; não opere o que você não sabe operar.
A3: Quem fez (função)
A4: Quem acompanhou
A6: Item | B6: Tipo de ponto | C6: Verifique | D6: Crítico | E6: Esperado | F6: Resposta (S / N / ? / NA) | G6: Foto nº | H6: Observação | I6: Status
A7: 1.1 | B7: Reposição do circuito (chiller, torre, caldeira, aquecimento) | C7: Localizei onde a água potável entra em cada circuito e anotei o local | D7: ★ | E7: S | I7: =IF(F7="","Pendente",IF(F7="NA","N/A",IF(E7="info","Info",IF(F7="?",IF(D7="★","VERMELHO","AMARELO"),IF(F7=E7,"OK",IF(D7="★","VERMELHO","AMARELO"))))))
A8: 1.2 | B8: Reposição do circuito (chiller, torre, caldeira, aquecimento) | C8: A reposição é automática (válvula, boia ou solenoide)? (N = é manual) | E8: info | I8: =IF(F8="","Pendente",IF(F8="NA","N/A",IF(E8="info","Info",IF(F8="?",IF(D8="★","VERMELHO","AMARELO"),IF(F8=E8,"OK",IF(D8="★","VERMELHO","AMARELO"))))))
A9: 1.3 | B9: Reposição do circuito (chiller, torre, caldeira, aquecimento) | C9: Existe folga de ar visível (separação atmosférica) entre a saída do potável e o tanque/circuito? | D9: ★ | E9: S | I9: =IF(F9="","Pendente",IF(F9="NA","N/A",IF(E9="info","Info",IF(F9="?",IF(D9="★","VERMELHO","AMARELO"),IF(F9=E9,"OK",IF(D9="★","VERMELHO","AMARELO"))))))
A10: 1.4 | B10: Reposição do circuito (chiller, torre, caldeira, aquecimento) | C10: Se não há folga de ar: existe dispositivo antirretorno com plaqueta legível (tipo e data)? (NA se há folga de ar) | D10: ★ | E10: S | I10: =IF(F10="","Pendente",IF(F10="NA","N/A",IF(E10="info","Info",IF(F10="?",IF(D10="★","VERMELHO","AMARELO"),IF(F10=E10,"OK",IF(D10="★","VERMELHO","AMARELO"))))))
A11: 1.5 | B11: Reposição do circuito (chiller, torre, caldeira, aquecimento) | C11: Existe registro de teste desse dispositivo por profissional habilitado, com data? (NA se há folga de ar) | D11: ★ | E11: S | I11: =IF(F11="","Pendente",IF(F11="NA","N/A",IF(E11="info","Info",IF(F11="?",IF(D11="★","VERMELHO","AMARELO"),IF(F11=E11,"OK",IF(D11="★","VERMELHO","AMARELO"))))))
A12: 1.6 | B12: Reposição do circuito (chiller, torre, caldeira, aquecimento) | C12: Há mangueira, engate rápido, jumper ou ligação provisória conectada ou guardada no ponto de reposição? (S = risco) | D12: ★ | E12: N | I12: =IF(F12="","Pendente",IF(F12="NA","N/A",IF(E12="info","Info",IF(F12="?",IF(D12="★","VERMELHO","AMARELO"),IF(F12=E12,"OK",IF(D12="★","VERMELHO","AMARELO"))))))
A13: 1.7 | B13: Reposição do circuito (chiller, torre, caldeira, aquecimento) | C13: Se há bypass da válvula automática: está fechado, lacrado e identificado? (NA se não há bypass) | E13: S | I13: =IF(F13="","Pendente",IF(F13="NA","N/A",IF(E13="info","Info",IF(F13="?",IF(D13="★","VERMELHO","AMARELO"),IF(F13=E13,"OK",IF(D13="★","VERMELHO","AMARELO"))))))
A14: 1.8 | B14: Reposição do circuito (chiller, torre, caldeira, aquecimento) | C14: Há hidrômetro ou registro da reposição (litros) e livro de registro da reposição manual (quem, quando, quantos litros)? | E14: S | I14: =IF(F14="","Pendente",IF(F14="NA","N/A",IF(E14="info","Info",IF(F14="?",IF(D14="★","VERMELHO","AMARELO"),IF(F14=E14,"OK",IF(D14="★","VERMELHO","AMARELO"))))))
A15: 1.9 | B15: Reposição do circuito (chiller, torre, caldeira, aquecimento) | C15: Há vazamento visível no circuito (válvulas, flanges, bombas) ou sinal de reposição acima do normal? (S = risco) | E15: N | I15: =IF(F15="","Pendente",IF(F15="NA","N/A",IF(E15="info","Info",IF(F15="?",IF(D15="★","VERMELHO","AMARELO"),IF(F15=E15,"OK",IF(D15="★","VERMELHO","AMARELO"))))))
A16: 1.10 | B16: Reposição do circuito (chiller, torre, caldeira, aquecimento) | C16: O ladrão ou extravasor do tanque de expansão/reposição vai para algum reservatório de água potável? (S = risco) | D16: ★ | E16: N | I16: =IF(F16="","Pendente",IF(F16="NA","N/A",IF(E16="info","Info",IF(F16="?",IF(D16="★","VERMELHO","AMARELO"),IF(F16=E16,"OK",IF(D16="★","VERMELHO","AMARELO"))))))
A17: 1.11 | B17: Reposição do circuito (chiller, torre, caldeira, aquecimento) | C17: Alguma tubulação do circuito passa sobre ou dentro de reservatório de potável? (S = risco) | D17: ★ | E17: N | I17: =IF(F17="","Pendente",IF(F17="NA","N/A",IF(E17="info","Info",IF(F17="?",IF(D17="★","VERMELHO","AMARELO"),IF(F17=E17,"OK",IF(D17="★","VERMELHO","AMARELO"))))))
A18: 1.12 | B18: Reposição do circuito (chiller, torre, caldeira, aquecimento) | C18: A linha de dosagem química liga em algum ponto com água potável? (S = risco) | E18: N | I18: =IF(F18="","Pendente",IF(F18="NA","N/A",IF(E18="info","Info",IF(F18="?",IF(D18="★","VERMELHO","AMARELO"),IF(F18=E18,"OK",IF(D18="★","VERMELHO","AMARELO"))))))
A19: 1.13 | B19: Reposição do circuito (chiller, torre, caldeira, aquecimento) | C19: Há kit de reposição manual segura (tanque com folga de ar + bomba de transferência) e procedimento por escrito? | E19: S | I19: =IF(F19="","Pendente",IF(F19="NA","N/A",IF(E19="info","Info",IF(F19="?",IF(D19="★","VERMELHO","AMARELO"),IF(F19=E19,"OK",IF(D19="★","VERMELHO","AMARELO"))))))
A20: 1.14 | B20: Reposição do circuito (chiller, torre, caldeira, aquecimento) | C20: Existe traçador (corante) no circuito e está visível (torneira sentinela, visor)? | E20: S | I20: =IF(F20="","Pendente",IF(F20="NA","N/A",IF(E20="info","Info",IF(F20="?",IF(D20="★","VERMELHO","AMARELO"),IF(F20=E20,"OK",IF(D20="★","VERMELHO","AMARELO"))))))
A21: 2.1 | B21: Reúso | C21: Existe água de reúso no prédio? Anotar a origem (ETE, água cinza, chuva). (NA nos demais itens do tipo 2 se N) | E21: info | I21: =IF(F21="","Pendente",IF(F21="NA","N/A",IF(E21="info","Info",IF(F21="?",IF(D21="★","VERMELHO","AMARELO"),IF(F21=E21,"OK",IF(D21="★","VERMELHO","AMARELO"))))))
A22: 2.2 | B22: Reúso | C22: Toda a tubulação de reúso está identificada visualmente (cor, faixa, placa) nos trechos visíveis, inclusive forro e casa de máquinas? | D22: ★ | E22: S | I22: =IF(F22="","Pendente",IF(F22="NA","N/A",IF(E22="info","Info",IF(F22="?",IF(D22="★","VERMELHO","AMARELO"),IF(F22=E22,"OK",IF(D22="★","VERMELHO","AMARELO"))))))
A23: 2.3 | B23: Reúso | C23: Os pontos de uso (descarga, irrigação, lavagem) têm placa 'ÁGUA NÃO POTÁVEL'? Torneira de reúso sem volante comum ou com acesso restrito? | E23: S | I23: =IF(F23="","Pendente",IF(F23="NA","N/A",IF(E23="info","Info",IF(F23="?",IF(D23="★","VERMELHO","AMARELO"),IF(F23=E23,"OK",IF(D23="★","VERMELHO","AMARELO"))))))
A24: 2.4 | B24: Reúso | C24: Existe válvula de transferência, bypass ou interligação entre reúso e potável? (S = risco) | D24: ★ | E24: N | I24: =IF(F24="","Pendente",IF(F24="NA","N/A",IF(E24="info","Info",IF(F24="?",IF(D24="★","VERMELHO","AMARELO"),IF(F24=E24,"OK",IF(D24="★","VERMELHO","AMARELO"))))))
A25: 2.5 | B25: Reúso | C25: Se existe: está fechada, lacrada e identificada? Quem guarda a chave? (NA se não existe interligação) | D25: ★ | E25: S | I25: =IF(F25="","Pendente",IF(F25="NA","N/A",IF(E25="info","Info",IF(F25="?",IF(D25="★","VERMELHO","AMARELO"),IF(F25=E25,"OK",IF(D25="★","VERMELHO","AMARELO"))))))
A26: 2.6 | B26: Reúso | C26: O reservatório de reúso é reposto com potável? Se sim, há folga de ar nessa reposição? (NA se não é reposto com potável) | D26: ★ | E26: S | I26: =IF(F26="","Pendente",IF(F26="NA","N/A",IF(E26="info","Info",IF(F26="?",IF(D26="★","VERMELHO","AMARELO"),IF(F26=E26,"OK",IF(D26="★","VERMELHO","AMARELO"))))))
A27: 2.7 | B27: Reúso | C27: Há tubulação de reúso e de potável lado a lado sem identificação clara? (S = risco) | E27: N | I27: =IF(F27="","Pendente",IF(F27="NA","N/A",IF(E27="info","Info",IF(F27="?",IF(D27="★","VERMELHO","AMARELO"),IF(F27=E27,"OK",IF(D27="★","VERMELHO","AMARELO"))))))
A28: 2.8 | B28: Reúso | C28: Há bebedouro, copa ou torneira de uso potável perto de ponto de reúso? (S = risco) | E28: N | I28: =IF(F28="","Pendente",IF(F28="NA","N/A",IF(E28="info","Info",IF(F28="?",IF(D28="★","VERMELHO","AMARELO"),IF(F28=E28,"OK",IF(D28="★","VERMELHO","AMARELO"))))))
A29: 2.9 | B29: Reúso | C29: O traçador (corante) do reúso continua presente e visível? | E29: S | I29: =IF(F29="","Pendente",IF(F29="NA","N/A",IF(E29="info","Info",IF(F29="?",IF(D29="★","VERMELHO","AMARELO"),IF(F29=E29,"OK",IF(D29="★","VERMELHO","AMARELO"))))))
A30: 3.1 | B30: Reserva e rede de incêndio | C30: A reserva de incêndio é reposta pela rede potável? Se sim, há folga de ar? (NA se não é reposta pela rede potável) | D30: ★ | E30: S | I30: =IF(F30="","Pendente",IF(F30="NA","N/A",IF(E30="info","Info",IF(F30="?",IF(D30="★","VERMELHO","AMARELO"),IF(F30=E30,"OK",IF(D30="★","VERMELHO","AMARELO"))))))
A31: 3.2 | B31: Reserva e rede de incêndio | C31: Se a reserva de incêndio é o mesmo reservatório da água de consumo: a saída do consumo fica acima do nível da reserva? (NA se reservatórios separados) | D31: ★ | E31: S | I31: =IF(F31="","Pendente",IF(F31="NA","N/A",IF(E31="info","Info",IF(F31="?",IF(D31="★","VERMELHO","AMARELO"),IF(F31=E31,"OK",IF(D31="★","VERMELHO","AMARELO"))))))
A32: 3.3 | B32: Reserva e rede de incêndio | C32: Existe conexão entre a rede de incêndio e a rede potável (válvula de reposição, jumper de teste)? (S = risco) | D32: ★ | E32: N | I32: =IF(F32="","Pendente",IF(F32="NA","N/A",IF(E32="info","Info",IF(F32="?",IF(D32="★","VERMELHO","AMARELO"),IF(F32=E32,"OK",IF(D32="★","VERMELHO","AMARELO"))))))
A33: 3.4 | B33: Reserva e rede de incêndio | C33: Em testes de bomba ou de sprinkler usa-se mangueira ligada ao potável? (S = risco) | E33: N | I33: =IF(F33="","Pendente",IF(F33="NA","N/A",IF(E33="info","Info",IF(F33="?",IF(D33="★","VERMELHO","AMARELO"),IF(F33=E33,"OK",IF(D33="★","VERMELHO","AMARELO"))))))
A34: 3.5 | B34: Reserva e rede de incêndio | C34: Se a rede de sprinklers tem aditivo (anticongelante, espuma): o ponto de reposição ou de teste é protegido contra refluxo? (NA se não há aditivo) | E34: S | I34: =IF(F34="","Pendente",IF(F34="NA","N/A",IF(E34="info","Info",IF(F34="?",IF(D34="★","VERMELHO","AMARELO"),IF(F34=E34,"OK",IF(D34="★","VERMELHO","AMARELO"))))))
A35: 3.6 | B35: Reserva e rede de incêndio | C35: Há registro das manobras de teste (data, quem, o que foi aberto)? | E35: S | I35: =IF(F35="","Pendente",IF(F35="NA","N/A",IF(E35="info","Info",IF(F35="?",IF(D35="★","VERMELHO","AMARELO"),IF(F35=E35,"OK",IF(D35="★","VERMELHO","AMARELO"))))))
A36: 4.1 | B36: Trocadores de calor (água quente × circuito químico) | C36: Existe trocador de calor entre o circuito com produto químico e a água potável (água quente)? Anotar tipo e localização. (NA nos demais itens do tipo 4 se N) | E36: info | I36: =IF(F36="","Pendente",IF(F36="NA","N/A",IF(E36="info","Info",IF(F36="?",IF(D36="★","VERMELHO","AMARELO"),IF(F36=E36,"OK",IF(D36="★","VERMELHO","AMARELO"))))))
A37: 4.2 | B37: Trocadores de calor (água quente × circuito químico) | C37: A parede é dupla (com detecção de vazamento)? Existe plaqueta ou documento que diga? | D37: ★ | E37: S | I37: =IF(F37="","Pendente",IF(F37="NA","N/A",IF(E37="info","Info",IF(F37="?",IF(D37="★","VERMELHO","AMARELO"),IF(F37=E37,"OK",IF(D37="★","VERMELHO","AMARELO"))))))
A38: 4.3 | B38: Trocadores de calor (água quente × circuito químico) | C38: O lado potável tem pressão maior que o lado químico? (só marque S se houver documento ou medição) | D38: ★ | E38: S | I38: =IF(F38="","Pendente",IF(F38="NA","N/A",IF(E38="info","Info",IF(F38="?",IF(D38="★","VERMELHO","AMARELO"),IF(F38=E38,"OK",IF(D38="★","VERMELHO","AMARELO"))))))
A39: 4.4 | B39: Trocadores de calor (água quente × circuito químico) | C39: Há dreno de inspeção ou indicador de vazamento no trocador? | E39: S | I39: =IF(F39="","Pendente",IF(F39="NA","N/A",IF(E39="info","Info",IF(F39="?",IF(D39="★","VERMELHO","AMARELO"),IF(F39=E39,"OK",IF(D39="★","VERMELHO","AMARELO"))))))
A40: 4.5 | B40: Trocadores de calor (água quente × circuito químico) | C40: Há registro da última inspeção de estanqueidade (data)? | E40: S | I40: =IF(F40="","Pendente",IF(F40="NA","N/A",IF(E40="info","Info",IF(F40="?",IF(D40="★","VERMELHO","AMARELO"),IF(F40=E40,"OK",IF(D40="★","VERMELHO","AMARELO"))))))
A41: 4.6 | B41: Trocadores de calor (água quente × circuito químico) | C41: O circuito químico perde água sem explicação? A reposição está aumentando? (S = risco) | E41: N | I41: =IF(F41="","Pendente",IF(F41="NA","N/A",IF(E41="info","Info",IF(F41="?",IF(D41="★","VERMELHO","AMARELO"),IF(F41=E41,"OK",IF(D41="★","VERMELHO","AMARELO"))))))
...

Sheet Incidentes
A1: Nº | B1: Data e hora do alerta | C1: Cenário (1-9) | D1: Ramo (A-F) | E1: Local (andar, ponto) | F1: O que foi observado | G1: Pessoas afetadas / atendimento | H1: Ações de contenção (o que, quem, hora) | I1: Níveis acionados | J1: Fornecedores / consultor acionados | K1: Coleta (pontos, laboratório) | L1: Causa confirmada | M1: Correção | N1: Limpeza e desinfecção | O1: Resultado das análises / parecer | P1: Autorização do síndico (data) | Q1: Comunicações enviadas | R1: Lições / atualização da ficha | S1: Status | T1: Dias em aberto
A2: 1 | T2: =IF(OR(B2="",S2="Encerrado"),"",INT(TODAY()-B2))
A3: 2 | T3: =IF(OR(B3="",S3="Encerrado"),"",INT(TODAY()-B3))
A4: 3 | T4: =IF(OR(B4="",S4="Encerrado"),"",INT(TODAY()-B4))
A5: 4 | T5: =IF(OR(B5="",S5="Encerrado"),"",INT(TODAY()-B5))
A6: 5 | T6: =IF(OR(B6="",S6="Encerrado"),"",INT(TODAY()-B6))
A7: 6 | T7: =IF(OR(B7="",S7="Encerrado"),"",INT(TODAY()-B7))
A8: 7 | T8: =IF(OR(B8="",S8="Encerrado"),"",INT(TODAY()-B8))
A9: 8 | T9: =IF(OR(B9="",S9="Encerrado"),"",INT(TODAY()-B9))
A10: 9 | T10: =IF(OR(B10="",S10="Encerrado"),"",INT(TODAY()-B10))
A11: 10 | T11: =IF(OR(B11="",S11="Encerrado"),"",INT(TODAY()-B11))
A12: 11 | T12: =IF(OR(B12="",S12="Encerrado"),"",INT(TODAY()-B12))
A13: 12 | T13: =IF(OR(B13="",S13="Encerrado"),"",INT(TODAY()-B13))
... A41: 40 | T41: =IF(OR(B41="",S41="Encerrado"),"",INT(TODAY()-B41))
